Workbook

Sheet Instrucciones
B2: BAHÍA MAR · Boutique Residence
B3: Las Terrenas, Samaná — República Dominicana
B4: FICHA DE LEVANTAMIENTO DE DATOS — Arquitectura · Producto · Precios | Uso interno · Landmass Capital, S.R.L.
B6: PARA QUÉ SIRVE ESTE ARCHIVO
B7: Recoge, de forma ordenada, TODOS los datos que necesitamos del arquitecto y de Landmass para fijar metrajes y precios de venta de Bahía Mar y cargarlos en Urbatrix. El arquitecto completa los m² y el mix; con eso el modelo calcula áreas vendibles y eficiencia, y luego Landmass coloca los precios finales.
B9: CÓMO USARLO
B10: 1) El arquitecto llena las celdas ROSA en la hoja 'Tipologias' (un renglón por tipo de villa) y, si lo tiene, el detalle unidad por unidad en 'Unidades'.
B11: 2) Las celdas GRISES se calculan solas (m² privativo total, eficiencia arquitectónica, totales). No se editan.
B12: 3) Landmass completa las celdas AMARILLAS de 'Datos_Landmass' (tierra, costos, deuda, comisiones, objetivo).
B13: 4) Como paso FINAL, se llenan las columnas de precio (AMARILLAS) y el archivo arroja precio por unidad y Gross Sell-Out.
B15: RESPONSABLE POR HOJA
B16: Hoja | C16: Quién la llena | D16: Qué entrega
B17: Tipologias | C17: Arquitecto | D17: Cuadro de m² por tipología (interior, terraza, roof, parcela, bruto) y nº de unidades de cada tipo.
B18: Unidades | C18: Arquitecto + Comercial | D18: Listado unidad por unidad (nivel, vista, estatus) listo para cargar en Urbatrix.
B19: Datos_Landmass | C19: Fernando / Landmass | D19: Condiciones comerciales y financieras: tierra, costos, deuda, comisiones, objetivo.
B20: Supuestos | C20: CFO (referencia) | D20: Estándares de mercado usados y definiciones de cada indicador.
B22: LEYENDA DE COLORES
C23: Campo a llenar por el ARQUITECTO
C24: Campo a definir por LANDMASS (incluye precios — paso final)
C25: Calculado automáticamente — NO editar
C26: Encabezado de tabla
B28: PUNTOS ABIERTOS A ACLARAR (detectados en el brochure)
B29: • El brochure indica 3 tipologías y 40 viviendas; el proyecto ahora maneja 5 tipologías → confirmar mix y total de unidades.
B30: • Villa I (Luxury): el resumen dice 160 m² (90+20+50) pero los planos suman ≈220 m² (PB 125,65 + PA 94,93) → definir m² oficiales.
B31: • Villa II (Penthouse): 'parcela a partir de 5 m²' parece error de tipeo → confirmar.
B32: • Faltan los m² de Villa Premium, de la villa insignia ('Villa A') y de la 5.ª tipología.
B33: • Parcela total del proyecto: 20.652 m²; zonas comunes: 650 m² (dato del brochure).
B35: Versión 1.0 — preparado por la oficina de CFO / Ingeniería Financiera, Landmass Capital. Cifras precargadas = BORRADOR a confirmar.

Sheet Tipologias
A1: DATOS
A2: IDENTIFICACIÓN | D2: PROGRAMA | I2: ÁREAS — ARQUITECTO (m²) | P2: CALCULADO | S2: PRECIOS — LANDMASS (paso final)
A3: Código | B3: Nombre tipología (provisional) | C3: Uso / descripción | D3: N° plantas | E3: Hab. | F3: Baños | G3: Vista | H3: N° unidades | I3: m² Interior privativo | J3: m² Terraza | K3: m² Roof / Solárium | L3: m² Parcela exterior | M3: m² Piscina | N3: m² Picuzzi | O3: m² Construido bruto | P3: m² Privativo total | Q3: Eficiencia arq. (Int/Bruto) | R3: m² Interior totales proy. | S3: $/m² objetivo | T3: Precio venta x unidad | U3: Gross Sell-Out tipología | V3: Notas / estado | W3: Adicional
A4: T1 | B4: VILLA A | C4: Villa de mayor programa, con áreas sociales amplias, cava de vinos, dormitorio de huéspedes, zona de servicio, piscina, solárium, fogata, picuzzi y terrazas. | D4: 2 | E4: 4 | F4: 4.5 | G4: Paisaje / piscina / terrazas / horizonte | H4: 32 | I4: 321.621 | J4: 94.982 | K4: 29 | L4: Variable según lote | M4: 21.28 | N4: 7 | O4: 421.223 | P4: =SUM(I4:K4) -> 445.603 | Q4: =IFERROR(I4/O4,"") -> 0.76354093 | R4: =IF(OR($H4="",I4=""),"",$H4*I4) -> 10291.872 | T4: =IF(OR($S4="",$S4=0,P4=0),"",$S4*P4) | U4: =IF(OR($H4="",$T4=""),"",$H4*$T4) | V4: BORRADOR brochure (Villa II Penthouse). Confirmar m² bruto, parcela y nº de unidades. | W4: **Incluye 1 baño de servicio independiente, no contabilizado dentro del número de baños principales de la villa.**
A5: T2 | B5: VILLA B | C5: Villa alargada y más compacta, con área social lineal, dormitorio de huéspedes en primer nivel, dos dormitorios en segundo nivel, piscina, solárium, fogata, picuzzi y terrazas superiores. | D5: 2 | E5: 3 | F5: 3.5 | G5: Paisaje / piscina / terrazas / horizonte | H5: 14 | I5: 179.174 | J5: 89 | K5: 33 | L5: Variable según lote | M5: 12 | N5: 4 | O5: 261.495 | P5: =SUM(I5:K5) -> 301.174 | Q5: =IFERROR(I5/O5,"") -> 0.68519092 | R5: =IF(OR($H5="",I5=""),"",$H5*I5) -> 2508.436 | T5: =IF(OR($S5="",$S5=0,P5=0),"",$S5*P5) | U5: =IF(OR($H5="",$T5=""),"",$H5*$T5) | V5: Faltan todos los m². Pendiente del arquitecto. | W5: **Incluye 1 baño de servicio independiente, no contabilizado dentro del número de baños principales de la villa.**
A6: T3 | B6: VILLA C | C6: Villa de un solo nivel, compacta y funcional, con sala, comedor, cocina, dormitorio principal, dormitorio secundario, área de servicio, piscina, solárium, fogata, picuzzi y terraza. | D6: 1 | E6: 2 | F6: 2.5 | G6: Paisaje / piscina / terrazas / horizonte | H6: 24 | I6: 154.388 | J6: 48 | K6: 31 | L6: Variable según lote | M6: 12 | N6: 4 | O6: 185 | P6: =SUM(I6:K6) -> 233.388 | Q6: =IFERROR(I6/O6,"") -> 0.83452973 | R6: =IF(OR($H6="",I6=""),"",$H6*I6) -> 3705.312 | T6: =IF(OR($S6="",$S6=0,P6=0),"",$S6*P6) | U6: =IF(OR($H6="",$T6=""),"",$H6*$T6) | V6: BORRADOR brochure (160 m²) NO cuadra con planos (~220 m²). Definir m² oficiales. | W6: **Incluye 1 baño de servicio independiente, no contabilizado dentro del número de baños principales de la villa.**
A7: T4 | B7: VILLA D | C7: Villa de un solo nivel, de estilo cálido, rústico y natural, con dos dormitorios, área social integrada, zona BBQ, piscina, solárium, fogata, picuzzi y terrazas. | D7: 1 | E7: 2 | F7: 2 | G7: Paisaje / piscina / terrazas / horizonte | H7: 84 | I7: 94.789 | J7: 83.65 | K7: 17.125 | L7: Variable según lote | M7: 17.8 | N7: 2.011 | O7: 108.863 | P7: =SUM(I7:K7) -> 195.564 | Q7: =IFERROR(I7/O7,"") -> 0.87071824 | R7: =IF(OR($H7="",I7=""),"",$H7*I7) -> 7962.276 | T7: =IF(OR($S7="",$S7=0,P7=0),"",$S7*P7) | U7: =IF(OR($H7="",$T7=""),"",$H7*$T7) | V7: Villa insignia (cava, BBQ, fogata, piscina). Faltan m². Confirmar nº de hab/baños. | W7: -
A8: T5 | B8: VILLA E | C8: Villa de dos niveles, con carácter tropical, cálido y natural. Integra dormitorio de huéspedes en primer nivel, dos dormitorios en segundo nivel, terrazas, piscina, picuzzi, zona BBQ, solárium y fogata. | D8: 2 | E8: 3 | F8: 3 | G8: Paisaje / piscina / terrazas / horizonte | H8: 79 | I8: 130.044 | J8: 91.53 | K8: 17.05 | L8: Variable según lote | M8: 27.563 | N8: 2.011 | O8: 163.537 | P8: =SUM(I8:K8) -> 238.624 | Q8: =IFERROR(I8/O8,"") -> 0.79519619 | R8: =IF(OR($H8="",I8=""),"",$H8*I8) -> 10273.476 | T8: =IF(OR($S8="",$S8=0,P8=0),"",$S8*P8) | U8: =IF(OR($H8="",$T8=""),"",$H8*$T8) | V8: Tipología no incluida en el brochure. Definir programa y m². | W8: -
A9: TOTAL | H9: =SUM(H4:H8) -> 233 | Q9: =IFERROR(SUMPRODUCT($H4:$H8,$I4:$I8)/SUMPRODUCT($H4:$H8,$O4:$O8),"") -> 0.79601749 | R9: =SUM(R4:R8) -> 34741.372 | U9: =SUM(U4:U8) -> 0 | V9: Eficiencia objetivo: 80%–85%
A11: Nota: la 'Eficiencia arq.' = m² interior privativo ÷ m² construido bruto. Objetivo del estándar RE: 80%–85%. Terraza, roof y parcela se valoran aparte en el precio si así se decide.
A12: Total de unidades del brochure = 40 (referencia). Confirmar con el arquitecto el nº por tipología.

Sheet Unidades
A1: LISTADO DE UNIDADES — carga Urbatrix (m², hab, baños y $/m² se traen solos desde 'Tipologias')
A2: N° / Nombre unidad | B2: Código tipología | C2: Etapa / Fase | D2: Nivel | E2: Vista | F2: Hab. | G2: Baños | H2: m² Interior | I2: m² Terraza | J2: m² Total privativo | K2: Estatus | L2: Lista precio | M2: $/m² | N2: Precio venta | O2: Reserva | P2: Broker asignado | Q2: Notas
A3: A-001 | B3: T1 | C3: Fase 4 | D3: 2 | E3: Paisaje / piscina / terrazas / horizonte | F3: =IFERROR(VLOOKUP($B3,Tipologias!$A$4:$V$8,5,0),"") -> 4 | G3: =IFERROR(VLOOKUP($B3,Tipologias!$A$4:$V$8,6,0),"") -> 4.5 | H3: =IFERROR(VLOOKUP($B3,Tipologias!$A$4:$V$8,9,0),"") -> 321.621 | I3: =IFERROR(VLOOKUP($B3,Tipologias!$A$4:$V$8,10,0),"") -> 94.982 | J3: =IFERROR(VLOOKUP($B3,Tipologias!$A$4:$V$8,16,0),"") -> 445.603 | K3: Disponible | M3: =IFERROR(VLOOKUP($B3,Tipologias!$A$4:$V$8,19,0),"") | N3: =IF(OR($M3="",$J3=""),"",$M3*$J3) | Q3: Área lote: 1004.58 m² | Tipología temporal del plano
A4: A-002 | B4: T1 | C4: Fase 4 | D4: 2 | E4: Paisaje / piscina / terrazas / horizonte | F4: =IFERROR(VLOOKUP($B4,Tipologias!$A$4:$V$8,5,0),"") -> 4 | G4: =IFERROR(VLOOKUP($B4,Tipologias!$A$4:$V$8,6,0),"") -> 4.5 | H4: =IFERROR(VLOOKUP($B4,Tipologias!$A$4:$V$8,9,0),"") -> 321.621 | I4: =IFERROR(VLOOKUP($B4,Tipologias!$A$4:$V$8,10,0),"") -> 94.982 | J4: =IFERROR(VLOOKUP($B4,Tipologias!$A$4:$V$8,16,0),"") -> 445.603 | K4: Disponible | M4: =IFERROR(VLOOKUP($B4,Tipologias!$A$4:$V$8,19,0),"") | N4: =IF(OR($M4="",$J4=""),"",$M4*$J4) | Q4: Área lote: 1067.40 m² | Tipología temporal del plano
A5: A-003 | B5: T1 | C5: Fase 4 | D5: 2 | E5: Paisaje / piscina / terrazas / horizonte | F5: =IFERROR(VLOOKUP($B5,Tipologias!$A$4:$V$8,5,0),"") -> 4 | G5: =IFERROR(VLOOKUP($B5,Tipologias!$A$4:$V$8,6,0),"") -> 4.5 | H5: =IFERROR(VLOOKUP($B5,Tipologias!$A$4:$V$8,9,0),"") -> 321.621 | I5: =IFERROR(VLOOKUP($B5,Tipologias!$A$4:$V$8,10,0),"") -> 94.982 | J5: =IFERROR(VLOOKUP($B5,Tipologias!$A$4:$V$8,16,0),"") -> 445.603 | K5: Disponible | M5: =IFERROR(VLOOKUP($B5,Tipologias!$A$4:$V$8,19,0),"") | N5: =IF(OR($M5="",$J5=""),"",$M5*$J5) | Q5: Área lote: 772.20 m² | Tipología temporal del plano
A6: A-004 | B6: T1 | C6: Fase 4 | D6: 2 | E6: Paisaje / piscina / terrazas / horizonte | F6: =IFERROR(VLOOKUP($B6,Tipologias!$A$4:$V$8,5,0),"") -> 4 | G6: =IFERROR(VLOOKUP($B6,Tipologias!$A$4:$V$8,6,0),"") -> 4.5 | H6: =IFERROR(VLOOKUP($B6,Tipologias!$A$4:$V$8,9,0),"") -> 321.621 | I6: =IFERROR(VLOOKUP($B6,Tipologias!$A$4:$V$8,10,0),"") -> 94.982 | J6: =IFERROR(VLOOKUP($B6,Tipologias!$A$4:$V$8,16,0),"") -> 445.603 | K6: Disponible | M6: =IFERROR(VLOOKUP($B6,Tipologias!$A$4:$V$8,19,0),"") | N6: =IF(OR($M6="",$J6=""),"",$M6*$J6) | Q6: Área lote: 794.87 m² | Tipología temporal del plano
A7: A-005 | B7: T1 | C7: Fase 4 | D7: 2 | E7: Paisaje / piscina / terrazas / horizonte | F7: =IFERROR(VLOOKUP($B7,Tipologias!$A$4:$V$8,5,0),"") -> 4 | G7: =IFERROR(VLOOKUP($B7,Tipologias!$A$4:$V$8,6,0),"") -> 4.5 | H7: =IFERROR(VLOOKUP($B7,Tipologias!$A$4:$V$8,9,0),"") -> 321.621 | I7: =IFERROR(VLOOKUP($B7,Tipologias!$A$4:$V$8,10,0),"") -> 94.982 | J7: =IFERROR(VLOOKUP($B7,Tipologias!$A$4:$V$8,16,0),"") -> 445.603 | K7: Disponible | M7: =IFERROR(VLOOKUP($B7,Tipologias!$A$4:$V$8,19,0),"") | N7: =IF(OR($M7="",$J7=""),"",$M7*$J7) | Q7: Área lote: 801.89 m² | Tipología temporal del plano
A8: A-006 | B8: T1 | C8: Fase 4 | D8: 2 | E8: Paisaje / piscina / terrazas / horizonte | F8: =IFERROR(VLOOKUP($B8,Tipologias!$A$4:$V$8,5,0),"") -> 4 | G8: =IFERROR(VLOOKUP($B8,Tipologias!$A$4:$V$8,6,0),"") -> 4.5 | H8: =IFERROR(VLOOKUP($B8,Tipologias!$A$4:$V$8,9,0),"") -> 321.621 | I8: =IFERROR(VLOOKUP($B8,Tipologias!$A$4:$V$8,10,0),"") -> 94.982 | J8: =IFERROR(VLOOKUP($B8,Tipologias!$A$4:$V$8,16,0),"") -> 445.603 | K8: Disponible | M8: =IFERROR(VLOOKUP($B8,Tipologias!$A$4:$V$8,19,0),"") | N8: =IF(OR($M8="",$J8=""),"",$M8*$J8) | Q8: Área lote: 828.77 m² | Tipología temporal del plano
A9: A-007 | B9: T1 | C9: Fase 4 | D9: 2 | E9: Paisaje / piscina / terrazas / horizonte | F9: =IFERROR(VLOOKUP($B9,Tipologias!$A$4:$V$8,5,0),"") -> 4 | G9: =IFERROR(VLOOKUP($B9,Tipologias!$A$4:$V$8,6,0),"") -> 4.5 | H9: =IFERROR(VLOOKUP($B9,Tipologias!$A$4:$V$8,9,0),"") -> 321.621 | I9: =IFERROR(VLOOKUP($B9,Tipologias!$A$4:$V$8,10,0),"") -> 94.982 | J9: =IFERROR(VLOOKUP($B9,Tipologias!$A$4:$V$8,16,0),"") -> 445.603 | K9: Disponible | M9: =IFERROR(VLOOKUP($B9,Tipologias!$A$4:$V$8,19,0),"") | N9: =IF(OR($M9="",$J9=""),"",$M9*$J9) | Q9: Área lote: 788.69 m² | Tipología temporal del plano
A10: A-008 | B10: T1 | C10: Fase 4 | D10: 2 | E10: Paisaje / piscina / terrazas / horizonte | F10: =IFERROR(VLOOKUP($B10,Tipologias!$A$4:$V$8,5,0),"") -> 4 | G10: =IFERROR(VLOOKUP($B10,Tipologias!$A$4:$V$8,6,0),"") -> 4.5 | H10: =IFERROR(VLOOKUP($B10,Tipologias!$A$4:$V$8,9,0),"") -> 321.621 | I10: =IFERROR(VLOOKUP($B10,Tipologias!$A$4:$V$8,10,0),"") -> 94.982 | J10: =IFERROR(VLOOKUP($B10,Tipologias!$A$4:$V$8,16,0),"") -> 445.603 | K10: Disponible | M10: =IFERROR(VLOOKUP($B10,Tipologias!$A$4:$V$8,19,0),"") | N10: =IF(OR($M10="",$J10=""),"",$M10*$J10) | Q10: Área lote: 1228.17 m² | Tipología temporal del plano
A11: A-009 | B11: T1 | C11: Fase 4 | D11: 2 | E11: Paisaje / piscina / terrazas / horizonte | F11: =IFERROR(VLOOKUP($B11,Tipologias!$A$4:$V$8,5,0),"") -> 4 | G11: =IFERROR(VLOOKUP($B11,Tipologias!$A$4:$V$8,6,0),"") -> 4.5 | H11: =IFERROR(VLOOKUP($B11,Tipologias!$A$4:$V$8,9,0),"") -> 321.621 | I11: =IFERROR(VLOOKUP($B11,Tipologias!$A$4:$V$8,10,0),"") -> 94.982 | J11: =IFERROR(VLOOKUP($B11,Tipologias!$A$4:$V$8,16,0),"") -> 445.603 | K11: Disponible | M11: =IFERROR(VLOOKUP($B11,Tipologias!$A$4:$V$8,19,0),"") | N11: =IF(OR($M11="",$J11=""),"",$M11*$J11) | Q11: Área lote: 932.00 m² | Tipología temporal del plano
A12: A-010 | B12: T1 | C12: Fase 4 | D12: 2 | E12: Paisaje / piscina / terrazas / horizonte | F12: =IFERROR(VLOOKUP($B12,Tipologias!$A$4:$V$8,5,0),"") -> 4 | G12: =IFERROR(VLOOKUP($B12,Tipologias!$A$4:$V$8,6,0),"") -> 4.5 | H12: =IFERROR(VLOOKUP($B12,Tipologias!$A$4:$V$8,9,0),"") -> 321.621 | I12: =IFERROR(VLOOKUP($B12,Tipologias!$A$4:$V$8,10,0),"") -> 94.982 | J12: =IFERROR(VLOOKUP($B12,Tipologias!$A$4:$V$8,16,0),"") -> 445.603 | K12: Disponible | M12: =IFERROR(VLOOKUP($B12,Tipologias!$A$4:$V$8,19,0),"") | N12: =IF(OR($M12="",$J12=""),"",$M12*$J12) | Q12: Área lote: 883.19 m² | Tipología temporal del plano
A13: A-011 | B13: T1 | C13: Fase 4 | D13: 2 | E13: Paisaje / piscina / terrazas / horizonte | F13: =IFERROR(VLOOKUP($B13,Tipologias!$A$4:$V$8,5,0),"") -> 4 | G13: =IFERROR(VLOOKUP($B13,Tipologias!$A$4:$V$8,6,0),"") -> 4.5 | H13: =IFERROR(VLOOKUP($B13,Tipologias!$A$4:$V$8,9,0),"") -> 321.621 | I13: =IFERROR(VLOOKUP($B13,Tipologias!$A$4:$V$8,10,0),"") -> 94.982 | J13: =IFERROR(VLOOKUP($B13,Tipologias!$A$4:$V$8,16,0),"") -> 445.603 | K13: Disponible | M13: =IFERROR(VLOOKUP($B13,Tipologias!$A$4:$V$8,19,0),"") | N13: =IF(OR($M13="",$J13=""),"",$M13*$J13) | Q13: Área lote: 811.64 m² | Tipología temporal del plano
A14: A-012 | B14: T1 | C14: Fase 4 | D14: 2 | E14: Paisaje / piscina / terrazas / horizonte | F14: =IFERROR(VLOOKUP($B14,Tipologias!$A$4:$V$8,5,0),"") -> 4 | G14: =IFERROR(VLOOKUP($B14,Tipologias!$A$4:$V$8,6,0),"") -> 4.5 | H14: =IFERROR(VLOOKUP($B14,Tipologias!$A$4:$V$8,9,0),"") -> 321.621 | I14: =IFERROR(VLOOKUP($B14,Tipologias!$A$4:$V$8,10,0),"") -> 94.982 | J14: =IFERROR(VLOOKUP($B14,Tipologias!$A$4:$V$8,16,0),"") -> 445.603 | K14: Disponible | M14: =IFERROR(VLOOKUP($B14,Tipologias!$A$4:$V$8,19,0),"") | N14: =IF(OR($M14="",$J14=""),"",$M14*$J14) | Q14: Área lote: 832.55 m² | Tipología temporal del plano
... A235: E-079 | B235: T5 | C235: Fase 2 | D235: 2 | E235: Paisaje / piscina / terrazas / horizonte | F235: =IFERROR(VLOOKUP($B235,Tipologias!$A$4:$V$8,5,0),"") -> 3 | G235: =IFERROR(VLOOKUP($B235,Tipologias!$A$4:$V$8,6,0),"") -> 3 | H235: =IFERROR(VLOOKUP($B235,Tipologias!$A$4:$V$8,9,0),"") -> 130.044 | I235: =IFERROR(VLOOKUP($B235,Tipologias!$A$4:$V$8,10,0),"") -> 91.53 | J235: =IFERROR(VLOOKUP($B235,Tipologias!$A$4:$V$8,16,0),"") -> 238.624 | K235: Disponible | M235: =IFERROR(VLOOKUP($B235,Tipologias!$A$4:$V$8,19,0),"") | N235: =IF(OR($M235="",$J235=""),"",$M235*$J235) | Q235: Área lote: 656.97 m² | Tipología temporal del plano

Sheet Datos_Landmass
A1: DATOS COMERCIALES Y FINANCIEROS — LANDMASS (no es para el arquitecto)
A2: Concepto | B2: Valor | C2: Unidad | D2: Quién aporta | E2: Notas / estado
A3: 1 · COMERCIAL
A4: Moneda base | B4: USD | D4: Landmass | E4: Urbatrix puede mostrar EUR/CAD/MXN como conversión.
A5: Tasa de cambio USD/DOP | C5: DOP/USD | D5: Landmass | E5: (estándar de mercado a confirmar) — solo si se vende en DOP.
A6: Reserva por unidad | C6: USD | D6: Landmass | E6: Makai usó US$5,000.
A7: ¿Reserva reembolsable? | C7: Sí/No | D7: Landmass
A8: % a la reserva / firma | C8: % | D8: Landmass
A9: % durante construcción | C9: % | D9: Landmass | E9: Debe sumar 100% con los otros dos.
A10: % contra entrega | C10: % | D10: Landmass
A11: Delta Lista 0 → Lista 1 | C11: % | D11: Landmass | E11: Plusvalía al cumplir hito.
A12: Hito que dispara Lista 1 | C12: texto | D12: Landmass | E12: Ej.: inicio de excavación.
A13: Delta Lista 1 → Lista 2 | C13: % | D13: Landmass
A14: Hito que dispara Lista 2 | C14: texto | D14: Landmass | E14: Ej.: obra gris completa.
A15: Fecha estimada de entrega | C15: fecha | D15: Landmass | E15: Por fase, si aplica.
A16: 2 · TIERRA
A17: Modalidad | C17: Directa/Ruta B/Mixto | D17: Landmass
A18: Monto de compra (si directa) | C18: USD | D18: Landmass
A19: Ruta B — % cap table al aportante | B19: 0.3 | C19: % | D19: Landmass | E19: (estándar a confirmar) — propuesta 30%.
A20: Ruta B — % flujo neto a CxP socio | C20: % | D20: Landmass | E20: (estándar a confirmar) — rango 10%–12% por unidad entregada.
A21: Valor referencial del terreno | C21: USD | D21: Landmass | E21: Para el cap table / equity.
A22: 3 · CONSTRUCCIÓN
A23: Costo de construcción | C23: USD/m² | D23: Arquitecto/Constructor | E23: (estándar a confirmar) — clave para el modelo.
A24: Hard Costs (% del costo de obra) | C24: % | D24: Constructor
A25: Soft Costs (% del costo de obra) | C25: % | D25: Constructor | E25: Diseño, permisos, fideicomiso, legal.
A26: Contingencia de construcción | C26: % | D26: CFO | E26: (estándar a confirmar) — rango 5%–10%.
A27: Plazo de obra | C27: meses | D27: Constructor
A28: N° de fases | C28: # | D28: Landmass
A29: 4 · FINANCIAMIENTO (DEUDA)
A30: ¿Préstamo interino? | C30: Sí/No | D30: Landmass
A31: Monto del préstamo | C31: USD | D31: Landmass
A32: Tasa anual | C32: % | D32: Banco | E32: (a confirmar)
A33: Plazo | C33: meses | D33: Banco
A34: 5 · OPEX / COMERCIAL
A35: Comisión de venta (brokers) | C35: % | D35: Landmass | E35: (estándar a confirmar) — rango 4%–6%.
A36: Presupuesto de marketing | C36: USD | D36: Landmass
A37: Fee de Desarrollo Landmass | C37: % | D37: Landmass | E37: Sobre costo o sobre ventas — definir base.
A38: 6 · INCENTIVOS / OBJETIVO
A39: ¿Aplica CONFOTUR? | C39: Sí/No | D39: Landmass | E39: Validar con asesor fiscal/legal certificado en RD.
A40: Margen neto objetivo | C40: % | D40: Landmass
...

Sheet Supuestos
A1: SUPUESTOS, ESTÁNDARES Y DEFINICIONES
A2: A · DATOS FÍSICOS CONFIRMADOS (brochure)
A3: Parcela total del proyecto | B3: 20,652 | C3: m² | D3: Brochure Master Plan.
A4: Zonas comunes | B4: 650 | C4: m² | D4: Brochure Master Plan.
A5: Ubicación | B5: Las Terrenas, Samaná | D5: ≈60 km de la ciudad de Samaná.
A6: Amenidades | B6: Piscina, beach club, restaurante, wellness, golf, store | D6: Brochure.
A8: B · ESTÁNDARES DE MERCADO (a confirmar)
A9: Eficiencia arquitectónica objetivo | B9: 80% – 85% | C9: Área vendible ÷ área bruta.
A10: Contingencia de construcción | B10: 5% – 10% | C10: Sobre hard costs.
A11: Comisión de venta | B11: 4% – 6% | C11: Brokers / fuerza de ventas.
A12: Tasa de descuento (WACC) | B12: 12% – 15% | C12: Estándar corporativo Landmass.
A13: Ruta B — cap table al aportante | B13: 30% | C13: Propuesta estándar de la firma.
A14: Ruta B — CxP socio | B14: 10% – 12% del flujo neto | C14: Por unidad vendida y entregada.
A16: C · DEFINICIONES
A17: Eficiencia arquitectónica | B17: m² interior privativo (vendible) ÷ m² construido bruto. Cuánto del área construida se traduce en metros vendibles.
A18: m² Privativo total | B18: Interior + terraza + roof de la unidad. Base sugerida para aplicar el $/m².
A19: Gross Sell-Out | B19: Suma de los precios de venta de todas las unidades (ingreso bruto potencial del proyecto).
A20: Pre-sales ladder | B20: Listas escalonadas (0/1/2) cuyo precio sube al cumplir hitos de obra, para capturar plusvalía.
A21: Ruta B (aporte de terreno) | B21: El dueño del suelo lo aporta a cambio del 30% del cap table + una CxP a socio que se amortiza con 10%–12% del flujo neto por unidad entregada. La CxP es drenaje de caja, no costo de obra.
A22: Cap Rate / Exit value | B22: Para activos en renta (comercial/hotelero): valor de salida = NOI ÷ cap rate.
A24: Aviso: esta herramienta es apoyo a la decisión, no sustituye asesoría fiscal, legal, notarial o contable certificada en RD (CONFOTUR, ITBI, fideicomiso, retenciones).
